Workbook
Name _Hlk20317136: #REF!
Name OLE_LINK40: #REF!

Sheet PLAN DE EJECUCION
C2: PLAN DE ACTIVIDADES PARA LA REVISIÓN TÉCNICA Y FUNCIONAL - SISTEMA | F2: [Nombre de Sistema]
C4: Actividades | D4: Fecha inicio | E4: Fecha Fin | F4: Estimación en días | G4: Estimación en días
B5: HITO 1 | C5: Planificación, analisis y Diseño de casos de prueba
B6: HITO 2 | C6: Instalación y despliegue del sistema
B7: HITO 3 | C7: Validación de la operatividad
B8: HITO 4 | C8: Ejecución de pruebas funcionales y técnicas
B9: HITO 5 | C9: Revisión y levantamiento de incidencias
B10: HITO 6 | C10: Pruebas de regresión
B11: HITO 7 | C11: Cierre de pruebas
F12: =SUM(F5:F11) -> 0 | G12: =SUM(G8,G5) -> 0
B14: TIPOS DE PRUEBA | C14: PUNTOS CRÍTICOS A REVISAR | D14: PROCESOS | E14: DETALLE | F14: DETALLE
F15: HITO | G15: ENCARGADO | H15: ESTADO
B16: PRUEBAS FUNCIONALES | F16: HITO 4 | G16: Alejandra Cárdenas
F17: HITO 4 | G17: Alejandra Cárdenas
F18: HITO 4 | G18: Alejandra Cárdenas
F19: HITO 4 | G19: Alejandra Cárdenas
F20: HITO 4 | G20: Alejandra Cárdenas
F21: HITO 4 | G21: Alejandra Cárdenas
F22: HITO 4 | G22: Alejandra Cárdenas
F23: HITO 4 | G23: Alejandra Cárdenas
F24: HITO 4 | G24: Alejandra Cárdenas
F25: HITO 4 | G25: Alejandra Cárdenas
F26: HITO 4 | G26: Alejandra Cárdenas
F27: HITO 4 | G27: Alejandra Cárdenas
F28: HITO 4 | G28: Alejandra Cárdenas
... F35: HITO 4 | G35: Alejandra Cárdenas
B36: PRUEBAS TÉCNICAS | C36: Documentación | D36: PT01 | E36: Crear documentos para las pruebas (Plan y Diseño de Casos de Prueba; Plan de revisión de sistema). | F36: HITO 1 | G36: Alejandra Cárdenas
C37: Documentación | D37: PT02 | E37: Análisis de documentación del Sistema. | F37: HITO 1 | G37: Alejandra Cárdenas
C38: Documentación | D38: PT03 | E38: Crear documentos de las pruebas realizadas (Informe de atención de solicitudes, Informe de incidencias). | F38: HITO 5 | G38: Alejandra Cárdenas
C39: Documentación | D39: PT04 | E39: Crear o actualizar documentos de las pruebas realizadas (Plan y Diseño de Casos de Prueba; Plan de revisión de sistema, Informe de atención de solicitudes, Informe de incidencias, Informe de resultados de pruebas de calidad, Informe de pruebas). | F39: HITO 7 | G39: Alejandra Cárdenas
C40: Configuración y Entorno | D40: PT05 | E40: Verificar entorno y configuración base | F40: HITO 2 | G40: Alejandra Cárdenas
C41: Estabilidad de Ambiente | D41: PT06 | E41: Verificar la estabilidad, navegación básica y ejecución de los módulos críticos bajo la versión de .NET framework 4.8.1. | F41: HITO 3 | G41: Alejandra Cárdenas
B42: PRUEBAS DE REGRESIÓN | C42: Revisión y levantamiento de incidencias | D42: PR01 | E42: Revisar y cerrar incidencias | F42: HITO 5 | G42: Alejandra Cárdenas
C43: Flujos Críticos de Regresión | D43: PR02 | E43: Ejecutar flujos críticos del sistema. | F43: HITO 6 | G43: Alejandra Cárdenas
B46: Leyenda
B47: BLOQUEANTE | C47: Funcionalidad con errores que no permiten continuar con la revisión
B48: PENDIENTE | C48: Funcionalidad pendiente de revisión por el equipo de QA
B49: EN PROCESO | C49: Funcionalidad en proceso de revisión por el equipo de QA
B50: CONCLUIDO | C50: Funcionalidad revisada completamente, pero se tiene incidencias pendientes
B51: CERRADO | C51: Funcionalidad revisada completamente, no se tiene incidencias pendientes
...

Sheet AVANCE EJECUCIÓN 
B2: =CONCATENATE("Pruebas de Certificación del Sistema ",TEXT('PLAN DE EJECUCION'!D5, "dd/mm/yyyy")," - ",TEXT('PLAN DE EJECUCION'!E11, "dd/mm/yyyy")) -> Pruebas de Certificación del Sistema 00/01/1900 - 00/01/1900
F4: =CONCATENATE("Resumen de Incidencias de la Revisión Funcional y Técnicas - Sistema ",'PLAN DE EJECUCION'!$F$2) -> Resumen de Incidencias de la Revisión Funcional y Técnicas - Sistema [Nombre de Sistema] | Q4: =CONCATENATE("Resumen de Avance de la Revisión Funcional y Técnicas - Sistema ",'PLAN DE EJECUCION'!$F$2) -> Resumen de Avance de la Revisión Funcional y Técnicas - Sistema [Nombre de Sistema]
B5: TIPOS DE PRUEBA | C5: PUNTOS CRÍTICOS A REVISAR | D5: PROCESOS | E5: ID-CP | F5: CASO DE PRUEBA | G5: RESULTADO ESPERADO | H5: Total Inc. | I5: Corregidas | J5: Pendientes QA | K5: Pendientes DEV | L5: Desestimado | M5: Mejora | N5: Responsable QA | O5: Estado | Q5: Responsable QA | R5: Total de Casos Asignado | S5: PENDIENTE | T5: EN PROCESO | U5: BLOQUEANTE | V5: CONCLUIDO | W5: CERRADO | X5: POSTERGADO | Y5: % de Avance
B6: PRUEBAS FUNCIONALES | E6: CP-EACS-001 | H6: =SUM(I6,J6,L6,M6) -> 0 | I6: {=SUMPRODUCT(COUNTIFS('CONSOLIDADO DE INCIDENCIAS'!$M$2:$M$50, 'AVANCE EJECUCIÓN '!$D6, 'CONSOLIDADO DE INCIDENCIAS'!$D$2:$D$50, 'CONSOLIDADO DE INCIDENCIAS'!$B$58:$B$59))} -> 0 | J6: {=SUMPRODUCT(COUNTIFS('CONSOLIDADO DE INCIDENCIAS'!$M$2:$M$50, 'AVANCE EJECUCIÓN '!$D6, 'CONSOLIDADO DE INCIDENCIAS'!$D$2:$D$50, 'CONSOLIDADO DE INCIDENCIAS'!$B$55:$B$57))} -> 0 | K6: {=SUMPRODUCT(COUNTIFS('CONSOLIDADO DE INCIDENCIAS'!$M$2:$M$50, 'AVANCE EJECUCIÓN '!$D6, 'CONSOLIDADO DE INCIDENCIAS'!$W$2:$W$50, 'CONSOLIDADO DE INCIDENCIAS'!$B$55:$B$57))} -> 0 | L6: =COUNTIFS('CONSOLIDADO DE INCIDENCIAS'!$M$2:$M$50,'AVANCE EJECUCIÓN '!$D6,'CONSOLIDADO DE INCIDENCIAS'!$D$2:$D$50,'CONSOLIDADO DE INCIDENCIAS'!$B$60) -> 0 | M6: =COUNTIFS('CONSOLIDADO DE INCIDENCIAS'!$M$2:$M$50,'AVANCE EJECUCIÓN '!$D6,'CONSOLIDADO DE INCIDENCIAS'!$D$2:$D$50,'CONSOLIDADO DE INCIDENCIAS'!$B$61) -> 0 | N6: Alejandra Cárdenas | Q6: Alejandra Cárdenas | R6: =SUM(S6:X6) -> 0 | S6: =COUNTIFS($N$6:$N$33,$Q6,$O$6:$O$33,$B$42) -> 0 | T6: =COUNTIFS($N$6:$N$33,$Q6,$O$6:$O$33,$B$43) -> 0 | U6: =COUNTIFS($N$6:$N$33,$Q6,$O$6:$O$33,$B$41) -> 0 | V6: =COUNTIFS($N$6:$N$33,$Q6,$O$6:$O$33,$B$44) -> 0 | W6: =COUNTIFS($N$6:$N$33,$Q6,$O$6:$O$33,$B$45) -> 0 | X6: =COUNTIFS($N$6:$N$33,$Q6,$O$6:$O$33,$B$46) -> 0 | Y6: =IFERROR(($X6+$W6+V6)/$R6, 0) -> 0
E7: CP-EACS-002 | H7: =SUM(I7,J7,L7,M7) -> 0 | I7: {=SUMPRODUCT(COUNTIFS('CONSOLIDADO DE INCIDENCIAS'!$M$2:$M$50, 'AVANCE EJECUCIÓN '!$D7, 'CONSOLIDADO DE INCIDENCIAS'!$D$2:$D$50, 'CONSOLIDADO DE INCIDENCIAS'!$B$58:$B$59))} -> 0 | J7: {=SUMPRODUCT(COUNTIFS('CONSOLIDADO DE INCIDENCIAS'!$M$2:$M$50, 'AVANCE EJECUCIÓN '!$D7, 'CONSOLIDADO DE INCIDENCIAS'!$D$2:$D$50, 'CONSOLIDADO DE INCIDENCIAS'!$B$55:$B$57))} -> 0 | K7: {=SUMPRODUCT(COUNTIFS('CONSOLIDADO DE INCIDENCIAS'!$M$2:$M$50, 'AVANCE EJECUCIÓN '!$D7, 'CONSOLIDADO DE INCIDENCIAS'!$W$2:$W$50, 'CONSOLIDADO DE INCIDENCIAS'!$B$55:$B$57))} -> 0 | L7: =COUNTIFS('CONSOLIDADO DE INCIDENCIAS'!$M$2:$M$50,'AVANCE EJECUCIÓN '!$D7,'CONSOLIDADO DE INCIDENCIAS'!$D$2:$D$50,'CONSOLIDADO DE INCIDENCIAS'!$B$60) -> 0 | M7: =COUNTIFS('CONSOLIDADO DE INCIDENCIAS'!$M$2:$M$50,'AVANCE EJECUCIÓN '!$D7,'CONSOLIDADO DE INCIDENCIAS'!$D$2:$D$50,'CONSOLIDADO DE INCIDENCIAS'!$B$61) -> 0 | N7: Alejandra Cárdenas | R7: =SUM(S7:X7) -> 0 | S7: =COUNTIFS($N$6:$N$33,$Q7,$O$6:$O$33,$B$42) -> 0 | T7: =COUNTIFS($N$6:$N$33,$Q7,$O$6:$O$33,$B$43) -> 0 | U7: =COUNTIFS($N$6:$N$33,$Q7,$O$6:$O$33,$B$41) -> 0 | V7: =COUNTIFS($N$6:$N$33,$Q7,$O$6:$O$33,$B$44) -> 0 | W7: =COUNTIFS($N$6:$N$33,$Q7,$O$6:$O$33,$B$45) -> 0 | X7: =COUNTIFS($N$6:$N$33,$Q7,$O$6:$O$33,$B$46) -> 0 | Y7: =IFERROR(($X7+$W7+V7)/$R7, 0) -> 0
E8: CP-EACS-003 | H8: =SUM(I8,J8,L8,M8) -> 0 | I8: {=SUMPRODUCT(COUNTIFS('CONSOLIDADO DE INCIDENCIAS'!$M$2:$M$50, 'AVANCE EJECUCIÓN '!$D8, 'CONSOLIDADO DE INCIDENCIAS'!$D$2:$D$50, 'CONSOLIDADO DE INCIDENCIAS'!$B$58:$B$59))} -> 0 | J8: {=SUMPRODUCT(COUNTIFS('CONSOLIDADO DE INCIDENCIAS'!$M$2:$M$50, 'AVANCE EJECUCIÓN '!$D8, 'CONSOLIDADO DE INCIDENCIAS'!$D$2:$D$50, 'CONSOLIDADO DE INCIDENCIAS'!$B$55:$B$57))} -> 0 | K8: {=SUMPRODUCT(COUNTIFS('CONSOLIDADO DE INCIDENCIAS'!$M$2:$M$50, 'AVANCE EJECUCIÓN '!$D8, 'CONSOLIDADO DE INCIDENCIAS'!$W$2:$W$50, 'CONSOLIDADO DE INCIDENCIAS'!$B$55:$B$57))} -> 0 | L8: =COUNTIFS('CONSOLIDADO DE INCIDENCIAS'!$M$2:$M$50,'AVANCE EJECUCIÓN '!$D8,'CONSOLIDADO DE INCIDENCIAS'!$D$2:$D$50,'CONSOLIDADO DE INCIDENCIAS'!$B$60) -> 0 | M8: =COUNTIFS('CONSOLIDADO DE INCIDENCIAS'!$M$2:$M$50,'AVANCE EJECUCIÓN '!$D8,'CONSOLIDADO DE INCIDENCIAS'!$D$2:$D$50,'CONSOLIDADO DE INCIDENCIAS'!$B$61) -> 0 | N8: Alejandra Cárdenas | R8: =SUM(S8:X8) -> 0 | S8: =COUNTIFS($N$6:$N$33,$Q8,$O$6:$O$33,$B$42) -> 0 | T8: =COUNTIFS($N$6:$N$33,$Q8,$O$6:$O$33,$B$43) -> 0 | U8: =COUNTIFS($N$6:$N$33,$Q8,$O$6:$O$33,$B$41) -> 0 | V8: =COUNTIFS($N$6:$N$33,$Q8,$O$6:$O$33,$B$44) -> 0 | W8: =COUNTIFS($N$6:$N$33,$Q8,$O$6:$O$33,$B$45) -> 0 | X8: =COUNTIFS($N$6:$N$33,$Q8,$O$6:$O$33,$B$46) -> 0 | Y8: =IFERROR(($X8+$W8+V8)/$R8, 0) -> 0
E9: CP-EACS-004 | H9: =SUM(I9,J9,L9,M9) -> 0 | I9: {=SUMPRODUCT(COUNTIFS('CONSOLIDADO DE INCIDENCIAS'!$M$2:$M$50, 'AVANCE EJECUCIÓN '!$D9, 'CONSOLIDADO DE INCIDENCIAS'!$D$2:$D$50, 'CONSOLIDADO DE INCIDENCIAS'!$B$58:$B$59))} -> 0 | J9: {=SUMPRODUCT(COUNTIFS('CONSOLIDADO DE INCIDENCIAS'!$M$2:$M$50, 'AVANCE EJECUCIÓN '!$D9, 'CONSOLIDADO DE INCIDENCIAS'!$D$2:$D$50, 'CONSOLIDADO DE INCIDENCIAS'!$B$55:$B$57))} -> 0 | K9: {=SUMPRODUCT(COUNTIFS('CONSOLIDADO DE INCIDENCIAS'!$M$2:$M$50, 'AVANCE EJECUCIÓN '!$D9, 'CONSOLIDADO DE INCIDENCIAS'!$W$2:$W$50, 'CONSOLIDADO DE INCIDENCIAS'!$B$55:$B$57))} -> 0 | L9: =COUNTIFS('CONSOLIDADO DE INCIDENCIAS'!$M$2:$M$50,'AVANCE EJECUCIÓN '!$D9,'CONSOLIDADO DE INCIDENCIAS'!$D$2:$D$50,'CONSOLIDADO DE INCIDENCIAS'!$B$60) -> 0 | M9: =COUNTIFS('CONSOLIDADO DE INCIDENCIAS'!$M$2:$M$50,'AVANCE EJECUCIÓN '!$D9,'CONSOLIDADO DE INCIDENCIAS'!$D$2:$D$50,'CONSOLIDADO DE INCIDENCIAS'!$B$61) -> 0 | N9: Alejandra Cárdenas | R9: =SUM(S9:X9) -> 0 | S9: =COUNTIFS($N$6:$N$33,$Q9,$O$6:$O$33,$B$42) -> 0 | T9: =COUNTIFS($N$6:$N$33,$Q9,$O$6:$O$33,$B$43) -> 0 | U9: =COUNTIFS($N$6:$N$33,$Q9,$O$6:$O$33,$B$41) -> 0 | V9: =COUNTIFS($N$6:$N$33,$Q9,$O$6:$O$33,$B$44) -> 0 | W9: =COUNTIFS($N$6:$N$33,$Q9,$O$6:$O$33,$B$45) -> 0 | X9: =COUNTIFS($N$6:$N$33,$Q9,$O$6:$O$33,$B$46) -> 0 | Y9: =IFERROR(($X9+$W9+V9)/$R9, 0) -> 0
E10: CP-EACS-005 | H10: =SUM(I10,J10,L10,M10) -> 0 | I10: {=SUMPRODUCT(COUNTIFS('CONSOLIDADO DE INCIDENCIAS'!$M$2:$M$50, 'AVANCE EJECUCIÓN '!$D10, 'CONSOLIDADO DE INCIDENCIAS'!$D$2:$D$50, 'CONSOLIDADO DE INCIDENCIAS'!$B$58:$B$59))} -> 0 | J10: {=SUMPRODUCT(COUNTIFS('CONSOLIDADO DE INCIDENCIAS'!$M$2:$M$50, 'AVANCE EJECUCIÓN '!$D10, 'CONSOLIDADO DE INCIDENCIAS'!$D$2:$D$50, 'CONSOLIDADO DE INCIDENCIAS'!$B$55:$B$57))} -> 0 | K10: {=SUMPRODUCT(COUNTIFS('CONSOLIDADO DE INCIDENCIAS'!$M$2:$M$50, 'AVANCE EJECUCIÓN '!$D10, 'CONSOLIDADO DE INCIDENCIAS'!$W$2:$W$50, 'CONSOLIDADO DE INCIDENCIAS'!$B$55:$B$57))} -> 0 | L10: =COUNTIFS('CONSOLIDADO DE INCIDENCIAS'!$M$2:$M$50,'AVANCE EJECUCIÓN '!$D10,'CONSOLIDADO DE INCIDENCIAS'!$D$2:$D$50,'CONSOLIDADO DE INCIDENCIAS'!$B$60) -> 0 | M10: =COUNTIFS('CONSOLIDADO DE INCIDENCIAS'!$M$2:$M$50,'AVANCE EJECUCIÓN '!$D10,'CONSOLIDADO DE INCIDENCIAS'!$D$2:$D$50,'CONSOLIDADO DE INCIDENCIAS'!$B$61) -> 0 | N10: Alejandra Cárdenas | R10: =SUM(S10:X10) -> 0 | S10: =COUNTIFS($N$6:$N$33,$Q10,$O$6:$O$33,$B$42) -> 0 | T10: =COUNTIFS($N$6:$N$33,$Q10,$O$6:$O$33,$B$43) -> 0 | U10: =COUNTIFS($N$6:$N$33,$Q10,$O$6:$O$33,$B$41) -> 0 | V10: =COUNTIFS($N$6:$N$33,$Q10,$O$6:$O$33,$B$44) -> 0 | W10: =COUNTIFS($N$6:$N$33,$Q10,$O$6:$O$33,$B$45) -> 0 | X10: =COUNTIFS($N$6:$N$33,$Q10,$O$6:$O$33,$B$46) -> 0 | Y10: =IFERROR(($X10+$W10+V10)/$R10, 0) -> 0
E11: CP-EACS-006 | H11: =SUM(I11,J11,L11,M11) -> 0 | I11: {=SUMPRODUCT(COUNTIFS('CONSOLIDADO DE INCIDENCIAS'!$M$2:$M$50, 'AVANCE EJECUCIÓN '!$D11, 'CONSOLIDADO DE INCIDENCIAS'!$D$2:$D$50, 'CONSOLIDADO DE INCIDENCIAS'!$B$58:$B$59))} -> 0 | J11: {=SUMPRODUCT(COUNTIFS('CONSOLIDADO DE INCIDENCIAS'!$M$2:$M$50, 'AVANCE EJECUCIÓN '!$D11, 'CONSOLIDADO DE INCIDENCIAS'!$D$2:$D$50, 'CONSOLIDADO DE INCIDENCIAS'!$B$55:$B$57))} -> 0 | K11: {=SUMPRODUCT(COUNTIFS('CONSOLIDADO DE INCIDENCIAS'!$M$2:$M$50, 'AVANCE EJECUCIÓN '!$D11, 'CONSOLIDADO DE INCIDENCIAS'!$W$2:$W$50, 'CONSOLIDADO DE INCIDENCIAS'!$B$55:$B$57))} -> 0 | L11: =COUNTIFS('CONSOLIDADO DE INCIDENCIAS'!$M$2:$M$50,'AVANCE EJECUCIÓN '!$D11,'CONSOLIDADO DE INCIDENCIAS'!$D$2:$D$50,'CONSOLIDADO DE INCIDENCIAS'!$B$60) -> 0 | M11: =COUNTIFS('CONSOLIDADO DE INCIDENCIAS'!$M$2:$M$50,'AVANCE EJECUCIÓN '!$D11,'CONSOLIDADO DE INCIDENCIAS'!$D$2:$D$50,'CONSOLIDADO DE INCIDENCIAS'!$B$61) -> 0 | N11: Alejandra Cárdenas | Q11: RESUMEN/TOTAL | R11: =SUM($R6:$R10) -> 0 | S11: =SUM(S6:S10) -> 0 | T11: =SUM(T6:T10) -> 0 | U11: =SUM(U6:U10) -> 0 | V11: =SUM(V6:V10) -> 0 | W11: =SUM(W6:W10) -> 0 | X11: =SUM(X6:X10) -> 0 | Y11: =IFERROR(($X11+$W11+V11)/$R11, 0) -> 0
E12: CP-EACS-007 | H12: =SUM(I12,J12,L12,M12) -> 0 | I12: {=SUMPRODUCT(COUNTIFS('CONSOLIDADO DE INCIDENCIAS'!$M$2:$M$50, 'AVANCE EJECUCIÓN '!$D12, 'CONSOLIDADO DE INCIDENCIAS'!$D$2:$D$50, 'CONSOLIDADO DE INCIDENCIAS'!$B$58:$B$59))} -> 0 | J12: {=SUMPRODUCT(COUNTIFS('CONSOLIDADO DE INCIDENCIAS'!$M$2:$M$50, 'AVANCE EJECUCIÓN '!$D12, 'CONSOLIDADO DE INCIDENCIAS'!$D$2:$D$50, 'CONSOLIDADO DE INCIDENCIAS'!$B$55:$B$57))} -> 0 | K12: {=SUMPRODUCT(COUNTIFS('CONSOLIDADO DE INCIDENCIAS'!$M$2:$M$50, 'AVANCE EJECUCIÓN '!$D12, 'CONSOLIDADO DE INCIDENCIAS'!$W$2:$W$50, 'CONSOLIDADO DE INCIDENCIAS'!$B$55:$B$57))} -> 0 | L12: =COUNTIFS('CONSOLIDADO DE INCIDENCIAS'!$M$2:$M$50,'AVANCE EJECUCIÓN '!$D12,'CONSOLIDADO DE INCIDENCIAS'!$D$2:$D$50,'CONSOLIDADO DE INCIDENCIAS'!$B$60) -> 0 | M12: =COUNTIFS('CONSOLIDADO DE INCIDENCIAS'!$M$2:$M$50,'AVANCE EJECUCIÓN '!$D12,'CONSOLIDADO DE INCIDENCIAS'!$D$2:$D$50,'CONSOLIDADO DE INCIDENCIAS'!$B$61) -> 0 | N12: Alejandra Cárdenas
E13: CP-EACS-008 | H13: =SUM(I13,J13,L13,M13) -> 0 | I13: {=SUMPRODUCT(COUNTIFS('CONSOLIDADO DE INCIDENCIAS'!$M$2:$M$50, 'AVANCE EJECUCIÓN '!$D13, 'CONSOLIDADO DE INCIDENCIAS'!$D$2:$D$50, 'CONSOLIDADO DE INCIDENCIAS'!$B$58:$B$59))} -> 0 | J13: {=SUMPRODUCT(COUNTIFS('CONSOLIDADO DE INCIDENCIAS'!$M$2:$M$50, 'AVANCE EJECUCIÓN '!$D13, 'CONSOLIDADO DE INCIDENCIAS'!$D$2:$D$50, 'CONSOLIDADO DE INCIDENCIAS'!$B$55:$B$57))} -> 0 | K13: {=SUMPRODUCT(COUNTIFS('CONSOLIDADO DE INCIDENCIAS'!$M$2:$M$50, 'AVANCE EJECUCIÓN '!$D13, 'CONSOLIDADO DE INCIDENCIAS'!$W$2:$W$50, 'CONSOLIDADO DE INCIDENCIAS'!$B$55:$B$57))} -> 0 | L13: =COUNTIFS('CONSOLIDADO DE INCIDENCIAS'!$M$2:$M$50,'AVANCE EJECUCIÓN '!$D13,'CONSOLIDADO DE INCIDENCIAS'!$D$2:$D$50,'CONSOLIDADO DE INCIDENCIAS'!$B$60) -> 0 | M13: =COUNTIFS('CONSOLIDADO DE INCIDENCIAS'!$M$2:$M$50,'AVANCE EJECUCIÓN '!$D13,'CONSOLIDADO DE INCIDENCIAS'!$D$2:$D$50,'CONSOLIDADO DE INCIDENCIAS'!$B$61) -> 0 | N13: Alejandra Cárdenas
E14: CP-EACS-009 | H14: =SUM(I14,J14,L14,M14) -> 0 | I14: {=SUMPRODUCT(COUNTIFS('CONSOLIDADO DE INCIDENCIAS'!$M$2:$M$50, 'AVANCE EJECUCIÓN '!$D14, 'CONSOLIDADO DE INCIDENCIAS'!$D$2:$D$50, 'CONSOLIDADO DE INCIDENCIAS'!$B$58:$B$59))} -> 0 | J14: {=SUMPRODUCT(COUNTIFS('CONSOLIDADO DE INCIDENCIAS'!$M$2:$M$50, 'AVANCE EJECUCIÓN '!$D14, 'CONSOLIDADO DE INCIDENCIAS'!$D$2:$D$50, 'CONSOLIDADO DE INCIDENCIAS'!$B$55:$B$57))} -> 0 | K14: {=SUMPRODUCT(COUNTIFS('CONSOLIDADO DE INCIDENCIAS'!$M$2:$M$50, 'AVANCE EJECUCIÓN '!$D14, 'CONSOLIDADO DE INCIDENCIAS'!$W$2:$W$50, 'CONSOLIDADO DE INCIDENCIAS'!$B$55:$B$57))} -> 0 | L14: =COUNTIFS('CONSOLIDADO DE INCIDENCIAS'!$M$2:$M$50,'AVANCE EJECUCIÓN '!$D14,'CONSOLIDADO DE INCIDENCIAS'!$D$2:$D$50,'CONSOLIDADO DE INCIDENCIAS'!$B$60) -> 0 | M14: =COUNTIFS('CONSOLIDADO DE INCIDENCIAS'!$M$2:$M$50,'AVANCE EJECUCIÓN '!$D14,'CONSOLIDADO DE INCIDENCIAS'!$D$2:$D$50,'CONSOLIDADO DE INCIDENCIAS'!$B$61) -> 0 | N14: Alejandra Cárdenas
E15: CP-EACS-010 | H15: =SUM(I15,J15,L15,M15) -> 0 | I15: {=SUMPRODUCT(COUNTIFS('CONSOLIDADO DE INCIDENCIAS'!$M$2:$M$50, 'AVANCE EJECUCIÓN '!$D15, 'CONSOLIDADO DE INCIDENCIAS'!$D$2:$D$50, 'CONSOLIDADO DE INCIDENCIAS'!$B$58:$B$59))} -> 0 | J15: {=SUMPRODUCT(COUNTIFS('CONSOLIDADO DE INCIDENCIAS'!$M$2:$M$50, 'AVANCE EJECUCIÓN '!$D15, 'CONSOLIDADO DE INCIDENCIAS'!$D$2:$D$50, 'CONSOLIDADO DE INCIDENCIAS'!$B$55:$B$57))} -> 0 | K15: {=SUMPRODUCT(COUNTIFS('CONSOLIDADO DE INCIDENCIAS'!$M$2:$M$50, 'AVANCE EJECUCIÓN '!$D15, 'CONSOLIDADO DE INCIDENCIAS'!$W$2:$W$50, 'CONSOLIDADO DE INCIDENCIAS'!$B$55:$B$57))} -> 0 | L15: =COUNTIFS('CONSOLIDADO DE INCIDENCIAS'!$M$2:$M$50,'AVANCE EJECUCIÓN '!$D15,'CONSOLIDADO DE INCIDENCIAS'!$D$2:$D$50,'CONSOLIDADO DE INCIDENCIAS'!$B$60) -> 0 | M15: =COUNTIFS('CONSOLIDADO DE INCIDENCIAS'!$M$2:$M$50,'AVANCE EJECUCIÓN '!$D15,'CONSOLIDADO DE INCIDENCIAS'!$D$2:$D$50,'CONSOLIDADO DE INCIDENCIAS'!$B$61) -> 0 | N15: Alejandra Cárdenas
E16: CP-EACS-011 | H16: =SUM(I16,J16,L16,M16) -> 0 | I16: {=SUMPRODUCT(COUNTIFS('CONSOLIDADO DE INCIDENCIAS'!$M$2:$M$50, 'AVANCE EJECUCIÓN '!$D16, 'CONSOLIDADO DE INCIDENCIAS'!$D$2:$D$50, 'CONSOLIDADO DE INCIDENCIAS'!$B$58:$B$59))} -> 0 | J16: {=SUMPRODUCT(COUNTIFS('CONSOLIDADO DE INCIDENCIAS'!$M$2:$M$50, 'AVANCE EJECUCIÓN '!$D16, 'CONSOLIDADO DE INCIDENCIAS'!$D$2:$D$50, 'CONSOLIDADO DE INCIDENCIAS'!$B$55:$B$57))} -> 0 | K16: {=SUMPRODUCT(COUNTIFS('CONSOLIDADO DE INCIDENCIAS'!$M$2:$M$50, 'AVANCE EJECUCIÓN '!$D16, 'CONSOLIDADO DE INCIDENCIAS'!$W$2:$W$50, 'CONSOLIDADO DE INCIDENCIAS'!$B$55:$B$57))} -> 0 | L16: =COUNTIFS('CONSOLIDADO DE INCIDENCIAS'!$M$2:$M$50,'AVANCE EJECUCIÓN '!$D16,'CONSOLIDADO DE INCIDENCIAS'!$D$2:$D$50,'CONSOLIDADO DE INCIDENCIAS'!$B$60) -> 0 | M16: =COUNTIFS('CONSOLIDADO DE INCIDENCIAS'!$M$2:$M$50,'AVANCE EJECUCIÓN '!$D16,'CONSOLIDADO DE INCIDENCIAS'!$D$2:$D$50,'CONSOLIDADO DE INCIDENCIAS'!$B$61) -> 0 | N16: Alejandra Cárdenas
E17: CP-EACS-012 | H17: =SUM(I17,J17,L17,M17) -> 0 | I17: {=SUMPRODUCT(COUNTIFS('CONSOLIDADO DE INCIDENCIAS'!$M$2:$M$50, 'AVANCE EJECUCIÓN '!$D17, 'CONSOLIDADO DE INCIDENCIAS'!$D$2:$D$50, 'CONSOLIDADO DE INCIDENCIAS'!$B$58:$B$59))} -> 0 | J17: {=SUMPRODUCT(COUNTIFS('CONSOLIDADO DE INCIDENCIAS'!$M$2:$M$50, 'AVANCE EJECUCIÓN '!$D17, 'CONSOLIDADO DE INCIDENCIAS'!$D$2:$D$50, 'CONSOLIDADO DE INCIDENCIAS'!$B$55:$B$57))} -> 0 | K17: {=SUMPRODUCT(COUNTIFS('CONSOLIDADO DE INCIDENCIAS'!$M$2:$M$50, 'AVANCE EJECUCIÓN '!$D17, 'CONSOLIDADO DE INCIDENCIAS'!$W$2:$W$50, 'CONSOLIDADO DE INCIDENCIAS'!$B$55:$B$57))} -> 0 | L17: =COUNTIFS('CONSOLIDADO DE INCIDENCIAS'!$M$2:$M$50,'AVANCE EJECUCIÓN '!$D17,'CONSOLIDADO DE INCIDENCIAS'!$D$2:$D$50,'CONSOLIDADO DE INCIDENCIAS'!$B$60) -> 0 | M17: =COUNTIFS('CONSOLIDADO DE INCIDENCIAS'!$M$2:$M$50,'AVANCE EJECUCIÓN '!$D17,'CONSOLIDADO DE INCIDENCIAS'!$D$2:$D$50,'CONSOLIDADO DE INCIDENCIAS'!$B$61) -> 0 | N17: Alejandra Cárdenas
E18: CP-EACS-013 | H18: =SUM(I18,J18,L18,M18) -> 0 | I18: {=SUMPRODUCT(COUNTIFS('CONSOLIDADO DE INCIDENCIAS'!$M$2:$M$50, 'AVANCE EJECUCIÓN '!$D18, 'CONSOLIDADO DE INCIDENCIAS'!$D$2:$D$50, 'CONSOLIDADO DE INCIDENCIAS'!$B$58:$B$59))} -> 0 | J18: {=SUMPRODUCT(COUNTIFS('CONSOLIDADO DE INCIDENCIAS'!$M$2:$M$50, 'AVANCE EJECUCIÓN '!$D18, 'CONSOLIDADO DE INCIDENCIAS'!$D$2:$D$50, 'CONSOLIDADO DE INCIDENCIAS'!$B$55:$B$57))} -> 0 | K18: {=SUMPRODUCT(COUNTIFS('CONSOLIDADO DE INCIDENCIAS'!$M$2:$M$50, 'AVANCE EJECUCIÓN '!$D18, 'CONSOLIDADO DE INCIDENCIAS'!$W$2:$W$50, 'CONSOLIDADO DE INCIDENCIAS'!$B$55:$B$57))} -> 0 | L18: =COUNTIFS('CONSOLIDADO DE INCIDENCIAS'!$M$2:$M$50,'AVANCE EJECUCIÓN '!$D18,'CONSOLIDADO DE INCIDENCIAS'!$D$2:$D$50,'CONSOLIDADO DE INCIDENCIAS'!$B$60) -> 0 | M18: =COUNTIFS('CONSOLIDADO DE INCIDENCIAS'!$M$2:$M$50,'AVANCE EJECUCIÓN '!$D18,'CONSOLIDADO DE INCIDENCIAS'!$D$2:$D$50,'CONSOLIDADO DE INCIDENCIAS'!$B$61) -> 0 | N18: Alejandra Cárdenas
E19: CP-EACS-014 | H19: =SUM(I19,J19,L19,M19) -> 0 | I19: {=SUMPRODUCT(COUNTIFS('CONSOLIDADO DE INCIDENCIAS'!$M$2:$M$50, 'AVANCE EJECUCIÓN '!$D19, 'CONSOLIDADO DE INCIDENCIAS'!$D$2:$D$50, 'CONSOLIDADO DE INCIDENCIAS'!$B$58:$B$59))} -> 0 | J19: {=SUMPRODUCT(COUNTIFS('CONSOLIDADO DE INCIDENCIAS'!$M$2:$M$50, 'AVANCE EJECUCIÓN '!$D19, 'CONSOLIDADO DE INCIDENCIAS'!$D$2:$D$50, 'CONSOLIDADO DE INCIDENCIAS'!$B$55:$B$57))} -> 0 | K19: {=SUMPRODUCT(COUNTIFS('CONSOLIDADO DE INCIDENCIAS'!$M$2:$M$50, 'AVANCE EJECUCIÓN '!$D19, 'CONSOLIDADO DE INCIDENCIAS'!$W$2:$W$50, 'CONSOLIDADO DE INCIDENCIAS'!$B$55:$B$57))} -> 0 | L19: =COUNTIFS('CONSOLIDADO DE INCIDENCIAS'!$M$2:$M$50,'AVANCE EJECUCIÓN '!$D19,'CONSOLIDADO DE INCIDENCIAS'!$D$2:$D$50,'CONSOLIDADO DE INCIDENCIAS'!$B$60) -> 0 | M19: =COUNTIFS('CONSOLIDADO DE INCIDENCIAS'!$M$2:$M$50,'AVANCE EJECUCIÓN '!$D19,'CONSOLIDADO DE INCIDENCIAS'!$D$2:$D$50,'CONSOLIDADO DE INCIDENCIAS'!$B$61) -> 0 | N19: Alejandra Cárdenas
E20: CP-EACS-015 | H20: =SUM(I20,J20,L20,M20) -> 0 | I20: {=SUMPRODUCT(COUNTIFS('CONSOLIDADO DE INCIDENCIAS'!$M$2:$M$50, 'AVANCE EJECUCIÓN '!$D20, 'CONSOLIDADO DE INCIDENCIAS'!$D$2:$D$50, 'CONSOLIDADO DE INCIDENCIAS'!$B$58:$B$59))} -> 0 | J20: {=SUMPRODUCT(COUNTIFS('CONSOLIDADO DE INCIDENCIAS'!$M$2:$M$50, 'AVANCE EJECUCIÓN '!$D20, 'CONSOLIDADO DE INCIDENCIAS'!$D$2:$D$50, 'CONSOLIDADO DE INCIDENCIAS'!$B$55:$B$57))} -> 0 | K20: {=SUMPRODUCT(COUNTIFS('CONSOLIDADO DE INCIDENCIAS'!$M$2:$M$50, 'AVANCE EJECUCIÓN '!$D20, 'CONSOLIDADO DE INCIDENCIAS'!$W$2:$W$50, 'CONSOLIDADO DE INCIDENCIAS'!$B$55:$B$57))} -> 0 | L20: =COUNTIFS('CONSOLIDADO DE INCIDENCIAS'!$M$2:$M$50,'AVANCE EJECUCIÓN '!$D20,'CONSOLIDADO DE INCIDENCIAS'!$D$2:$D$50,'CONSOLIDADO DE INCIDENCIAS'!$B$60) -> 0 | M20: =COUNTIFS('CONSOLIDADO DE INCIDENCIAS'!$M$2:$M$50,'AVANCE EJECUCIÓN '!$D20,'CONSOLIDADO DE INCIDENCIAS'!$D$2:$D$50,'CONSOLIDADO DE INCIDENCIAS'!$B$61) -> 0 | N20: Alejandra Cárdenas
E21: CP-EACS-016 | H21: =SUM(I21,J21,L21,M21) -> 0 | I21: {=SUMPRODUCT(COUNTIFS('CONSOLIDADO DE INCIDENCIAS'!$M$2:$M$50, 'AVANCE EJECUCIÓN '!$D21, 'CONSOLIDADO DE INCIDENCIAS'!$D$2:$D$50, 'CONSOLIDADO DE INCIDENCIAS'!$B$58:$B$59))} -> 0 | J21: {=SUMPRODUCT(COUNTIFS('CONSOLIDADO DE INCIDENCIAS'!$M$2:$M$50, 'AVANCE EJECUCIÓN '!$D21, 'CONSOLIDADO DE INCIDENCIAS'!$D$2:$D$50, 'CONSOLIDADO DE INCIDENCIAS'!$B$55:$B$57))} -> 0 | K21: {=SUMPRODUCT(COUNTIFS('CONSOLIDADO DE INCIDENCIAS'!$M$2:$M$50, 'AVANCE EJECUCIÓN '!$D21, 'CONSOLIDADO DE INCIDENCIAS'!$W$2:$W$50, 'CONSOLIDADO DE INCIDENCIAS'!$B$55:$B$57))} -> 0 | L21: =COUNTIFS('CONSOLIDADO DE INCIDENCIAS'!$M$2:$M$50,'AVANCE EJECUCIÓN '!$D21,'CONSOLIDADO DE INCIDENCIAS'!$D$2:$D$50,'CONSOLIDADO DE INCIDENCIAS'!$B$60) -> 0 | M21: =COUNTIFS('CONSOLIDADO DE INCIDENCIAS'!$M$2:$M$50,'AVANCE EJECUCIÓN '!$D21,'CONSOLIDADO DE INCIDENCIAS'!$D$2:$D$50,'CONSOLIDADO DE INCIDENCIAS'!$B$61) -> 0 | N21: Alejandra Cárdenas
E22: CP-EACS-017 | H22: =SUM(I22,J22,L22,M22) -> 0 | I22: {=SUMPRODUCT(COUNTIFS('CONSOLIDADO DE INCIDENCIAS'!$M$2:$M$50, 'AVANCE EJECUCIÓN '!$D22, 'CONSOLIDADO DE INCIDENCIAS'!$D$2:$D$50, 'CONSOLIDADO DE INCIDENCIAS'!$B$58:$B$59))} -> 0 | J22: {=SUMPRODUCT(COUNTIFS('CONSOLIDADO DE INCIDENCIAS'!$M$2:$M$50, 'AVANCE EJECUCIÓN '!$D22, 'CONSOLIDADO DE INCIDENCIAS'!$D$2:$D$50, 'CONSOLIDADO DE INCIDENCIAS'!$B$55:$B$57))} -> 0 | K22: {=SUMPRODUCT(COUNTIFS('CONSOLIDADO DE INCIDENCIAS'!$M$2:$M$50, 'AVANCE EJECUCIÓN '!$D22, 'CONSOLIDADO DE INCIDENCIAS'!$W$2:$W$50, 'CONSOLIDADO DE INCIDENCIAS'!$B$55:$B$57))} -> 0 | L22: =COUNTIFS('CONSOLIDADO DE INCIDENCIAS'!$M$2:$M$50,'AVANCE EJECUCIÓN '!$D22,'CONSOLIDADO DE INCIDENCIAS'!$D$2:$D$50,'CONSOLIDADO DE INCIDENCIAS'!$B$60) -> 0 | M22: =COUNTIFS('CONSOLIDADO DE INCIDENCIAS'!$M$2:$M$50,'AVANCE EJECUCIÓN '!$D22,'CONSOLIDADO DE INCIDENCIAS'!$D$2:$D$50,'CONSOLIDADO DE INCIDENCIAS'!$B$61) -> 0 | N22: Alejandra Cárdenas
E23: CP-EACS-018 | H23: =SUM(I23,J23,L23,M23) -> 0 | I23: {=SUMPRODUCT(COUNTIFS('CONSOLIDADO DE INCIDENCIAS'!$M$2:$M$50, 'AVANCE EJECUCIÓN '!$D23, 'CONSOLIDADO DE INCIDENCIAS'!$D$2:$D$50, 'CONSOLIDADO DE INCIDENCIAS'!$B$58:$B$59))} -> 0 | J23: {=SUMPRODUCT(COUNTIFS('CONSOLIDADO DE INCIDENCIAS'!$M$2:$M$50, 'AVANCE EJECUCIÓN '!$D23, 'CONSOLIDADO DE INCIDENCIAS'!$D$2:$D$50, 'CONSOLIDADO DE INCIDENCIAS'!$B$55:$B$57))} -> 0 | K23: {=SUMPRODUCT(COUNTIFS('CONSOLIDADO DE INCIDENCIAS'!$M$2:$M$50, 'AVANCE EJECUCIÓN '!$D23, 'CONSOLIDADO DE INCIDENCIAS'!$W$2:$W$50, 'CONSOLIDADO DE INCIDENCIAS'!$B$55:$B$57))} -> 0 | L23: =COUNTIFS('CONSOLIDADO DE INCIDENCIAS'!$M$2:$M$50,'AVANCE EJECUCIÓN '!$D23,'CONSOLIDADO DE INCIDENCIAS'!$D$2:$D$50,'CONSOLIDADO DE INCIDENCIAS'!$B$60) -> 0 | M23: =COUNTIFS('CONSOLIDADO DE INCIDENCIAS'!$M$2:$M$50,'AVANCE EJECUCIÓN '!$D23,'CONSOLIDADO DE INCIDENCIAS'!$D$2:$D$50,'CONSOLIDADO DE INCIDENCIAS'!$B$61) -> 0 | N23: Alejandra Cárdenas
... E25: CP-EACS-020 | H25: =SUM(I25,J25,L25,M25) -> 0 | I25: {=SUMPRODUCT(COUNTIFS('CONSOLIDADO DE INCIDENCIAS'!$M$2:$M$50, 'AVANCE EJECUCIÓN '!$D25, 'CONSOLIDADO DE INCIDENCIAS'!$D$2:$D$50, 'CONSOLIDADO DE INCIDENCIAS'!$B$58:$B$59))} -> 0 | J25: {=SUMPRODUCT(COUNTIFS('CONSOLIDADO DE INCIDENCIAS'!$M$2:$M$50, 'AVANCE EJECUCIÓN '!$D25, 'CONSOLIDADO DE INCIDENCIAS'!$D$2:$D$50, 'CONSOLIDADO DE INCIDENCIAS'!$B$55:$B$57))} -> 0 | K25: {=SUMPRODUCT(COUNTIFS('CONSOLIDADO DE INCIDENCIAS'!$M$2:$M$50, 'AVANCE EJECUCIÓN '!$D25, 'CONSOLIDADO DE INCIDENCIAS'!$W$2:$W$50, 'CONSOLIDADO DE INCIDENCIAS'!$B$55:$B$57))} -> 0 | L25: =COUNTIFS('CONSOLIDADO DE INCIDENCIAS'!$M$2:$M$50,'AVANCE EJECUCIÓN '!$D25,'CONSOLIDADO DE INCIDENCIAS'!$D$2:$D$50,'CONSOLIDADO DE INCIDENCIAS'!$B$60) -> 0 | M25: =COUNTIFS('CONSOLIDADO DE INCIDENCIAS'!$M$2:$M$50,'AVANCE EJECUCIÓN '!$D25,'CONSOLIDADO DE INCIDENCIAS'!$D$2:$D$50,'CONSOLIDADO DE INCIDENCIAS'!$B$61) -> 0 | N25: Alejandra Cárdenas
B26: PRUEBAS TÉCNICAS | C26: Documentación | D26: PT01 | E26: CP-EACS-021 | F26: Análisis de documentación del Sistema. | G26: Documentos del sistema analizados y considerados una línea base estable para las siguientes actividades. | H26: =SUM(I26,J26,L26,M26) -> 0 | I26: {=SUMPRODUCT(COUNTIFS('CONSOLIDADO DE INCIDENCIAS'!$M$2:$M$50, 'AVANCE EJECUCIÓN '!$D26, 'CONSOLIDADO DE INCIDENCIAS'!$D$2:$D$50, 'CONSOLIDADO DE INCIDENCIAS'!$B$58:$B$59))} -> 0 | J26: {=SUMPRODUCT(COUNTIFS('CONSOLIDADO DE INCIDENCIAS'!$M$2:$M$50, 'AVANCE EJECUCIÓN '!$D26, 'CONSOLIDADO DE INCIDENCIAS'!$D$2:$D$50, 'CONSOLIDADO DE INCIDENCIAS'!$B$55:$B$57))} -> 0 | K26: {=SUMPRODUCT(COUNTIFS('CONSOLIDADO DE INCIDENCIAS'!$M$2:$M$50, 'AVANCE EJECUCIÓN '!$D26, 'CONSOLIDADO DE INCIDENCIAS'!$W$2:$W$50, 'CONSOLIDADO DE INCIDENCIAS'!$B$55:$B$57))} -> 0 | L26: =COUNTIFS('CONSOLIDADO DE INCIDENCIAS'!$M$2:$M$50,'AVANCE EJECUCIÓN '!$D26,'CONSOLIDADO DE INCIDENCIAS'!$D$2:$D$50,'CONSOLIDADO DE INCIDENCIAS'!$B$60) -> 0 | M26: =COUNTIFS('CONSOLIDADO DE INCIDENCIAS'!$M$2:$M$50,'AVANCE EJECUCIÓN '!$D26,'CONSOLIDADO DE INCIDENCIAS'!$D$2:$D$50,'CONSOLIDADO DE INCIDENCIAS'!$B$61) -> 0 | N26: Alejandra Cárdenas
C27: Documentación | D27: PT02 | E27: CP-EACS-022 | F27: Crear documentos para las pruebas (Plan y Diseño de Casos de Prueba; Plan de revisión de sistema). | G27: Documentos redactados y aprobados | H27: =SUM(I27,J27,L27,M27) -> 0 | I27: {=SUMPRODUCT(COUNTIFS('CONSOLIDADO DE INCIDENCIAS'!$M$2:$M$50, 'AVANCE EJECUCIÓN '!$D27, 'CONSOLIDADO DE INCIDENCIAS'!$D$2:$D$50, 'CONSOLIDADO DE INCIDENCIAS'!$B$58:$B$59))} -> 0 | J27: {=SUMPRODUCT(COUNTIFS('CONSOLIDADO DE INCIDENCIAS'!$M$2:$M$50, 'AVANCE EJECUCIÓN '!$D27, 'CONSOLIDADO DE INCIDENCIAS'!$D$2:$D$50, 'CONSOLIDADO DE INCIDENCIAS'!$B$55:$B$57))} -> 0 | K27: {=SUMPRODUCT(COUNTIFS('CONSOLIDADO DE INCIDENCIAS'!$M$2:$M$50, 'AVANCE EJECUCIÓN '!$D27, 'CONSOLIDADO DE INCIDENCIAS'!$W$2:$W$50, 'CONSOLIDADO DE INCIDENCIAS'!$B$55:$B$57))} -> 0 | L27: =COUNTIFS('CONSOLIDADO DE INCIDENCIAS'!$M$2:$M$50,'AVANCE EJECUCIÓN '!$D27,'CONSOLIDADO DE INCIDENCIAS'!$D$2:$D$50,'CONSOLIDADO DE INCIDENCIAS'!$B$60) -> 0 | M27: =COUNTIFS('CONSOLIDADO DE INCIDENCIAS'!$M$2:$M$50,'AVANCE EJECUCIÓN '!$D27,'CONSOLIDADO DE INCIDENCIAS'!$D$2:$D$50,'CONSOLIDADO DE INCIDENCIAS'!$B$61) -> 0 | N27: Alejandra Cárdenas
C28: Documentación | D28: PT03 | E28: CP-EACS-023 | F28: Crear documentos de las pruebas realizadas (Informe de atención de solicitudes, Informe de incidencias). | G28: Documentos redactados y aprobados | H28: =SUM(I28,J28,L28,M28) -> 0 | I28: {=SUMPRODUCT(COUNTIFS('CONSOLIDADO DE INCIDENCIAS'!$M$2:$M$50, 'AVANCE EJECUCIÓN '!$D28, 'CONSOLIDADO DE INCIDENCIAS'!$D$2:$D$50, 'CONSOLIDADO DE INCIDENCIAS'!$B$58:$B$59))} -> 0 | J28: {=SUMPRODUCT(COUNTIFS('CONSOLIDADO DE INCIDENCIAS'!$M$2:$M$50, 'AVANCE EJECUCIÓN '!$D28, 'CONSOLIDADO DE INCIDENCIAS'!$D$2:$D$50, 'CONSOLIDADO DE INCIDENCIAS'!$B$55:$B$57))} -> 0 | K28: {=SUMPRODUCT(COUNTIFS('CONSOLIDADO DE INCIDENCIAS'!$M$2:$M$50, 'AVANCE EJECUCIÓN '!$D28, 'CONSOLIDADO DE INCIDENCIAS'!$W$2:$W$50, 'CONSOLIDADO DE INCIDENCIAS'!$B$55:$B$57))} -> 0 | L28: =COUNTIFS('CONSOLIDADO DE INCIDENCIAS'!$M$2:$M$50,'AVANCE EJECUCIÓN '!$D28,'CONSOLIDADO DE INCIDENCIAS'!$D$2:$D$50,'CONSOLIDADO DE INCIDENCIAS'!$B$60) -> 0 | M28: =COUNTIFS('CONSOLIDADO DE INCIDENCIAS'!$M$2:$M$50,'AVANCE EJECUCIÓN '!$D28,'CONSOLIDADO DE INCIDENCIAS'!$D$2:$D$50,'CONSOLIDADO DE INCIDENCIAS'!$B$61) -> 0 | N28: Alejandra Cárdenas
C29: Documentación | D29: PT04 | E29: CP-EACS-024 | F29: Crear o actualizar documentos de las pruebas realizadas (Plan y Diseño de Casos de Prueba; Plan de revisión de sistema, Informe de atención de solicitudes, Informe de incidencias, Informe de resultados de pruebas de calidad, Informe de pruebas). | G29: Documentos redactados y aprobados | H29: =SUM(I29,J29,L29,M29) -> 0 | I29: {=SUMPRODUCT(COUNTIFS('CONSOLIDADO DE INCIDENCIAS'!$M$2:$M$50, 'AVANCE EJECUCIÓN '!$D29, 'CONSOLIDADO DE INCIDENCIAS'!$D$2:$D$50, 'CONSOLIDADO DE INCIDENCIAS'!$B$58:$B$59))} -> 0 | J29: {=SUMPRODUCT(COUNTIFS('CONSOLIDADO DE INCIDENCIAS'!$M$2:$M$50, 'AVANCE EJECUCIÓN '!$D29, 'CONSOLIDADO DE INCIDENCIAS'!$D$2:$D$50, 'CONSOLIDADO DE INCIDENCIAS'!$B$55:$B$57))} -> 0 | K29: {=SUMPRODUCT(COUNTIFS('CONSOLIDADO DE INCIDENCIAS'!$M$2:$M$50, 'AVANCE EJECUCIÓN '!$D29, 'CONSOLIDADO DE INCIDENCIAS'!$W$2:$W$50, 'CONSOLIDADO DE INCIDENCIAS'!$B$55:$B$57))} -> 0 | L29: =COUNTIFS('CONSOLIDADO DE INCIDENCIAS'!$M$2:$M$50,'AVANCE EJECUCIÓN '!$D29,'CONSOLIDADO DE INCIDENCIAS'!$D$2:$D$50,'CONSOLIDADO DE INCIDENCIAS'!$B$60) -> 0 | M29: =COUNTIFS('CONSOLIDADO DE INCIDENCIAS'!$M$2:$M$50,'AVANCE EJECUCIÓN '!$D29,'CONSOLIDADO DE INCIDENCIAS'!$D$2:$D$50,'CONSOLIDADO DE INCIDENCIAS'!$B$61) -> 0 | N29: Alejandra Cárdenas
C30: Configuración y Entorno | D30: PT05 | E30: CP-EACS-025 | F30: Verificar entorno y configuración base | G30: Ambiente operativo, actualizados y sin bloqueos. | H30: =SUM(I30,J30,L30,M30) -> 0 | I30: {=SUMPRODUCT(COUNTIFS('CONSOLIDADO DE INCIDENCIAS'!$M$2:$M$50, 'AVANCE EJECUCIÓN '!$D30, 'CONSOLIDADO DE INCIDENCIAS'!$D$2:$D$50, 'CONSOLIDADO DE INCIDENCIAS'!$B$58:$B$59))} -> 0 | J30: {=SUMPRODUCT(COUNTIFS('CONSOLIDADO DE INCIDENCIAS'!$M$2:$M$50, 'AVANCE EJECUCIÓN '!$D30, 'CONSOLIDADO DE INCIDENCIAS'!$D$2:$D$50, 'CONSOLIDADO DE INCIDENCIAS'!$B$55:$B$57))} -> 0 | K30: {=SUMPRODUCT(COUNTIFS('CONSOLIDADO DE INCIDENCIAS'!$M$2:$M$50, 'AVANCE EJECUCIÓN '!$D30, 'CONSOLIDADO DE INCIDENCIAS'!$W$2:$W$50, 'CONSOLIDADO DE INCIDENCIAS'!$B$55:$B$57))} -> 0 | L30: =COUNTIFS('CONSOLIDADO DE INCIDENCIAS'!$M$2:$M$50,'AVANCE EJECUCIÓN '!$D30,'CONSOLIDADO DE INCIDENCIAS'!$D$2:$D$50,'CONSOLIDADO DE INCIDENCIAS'!$B$60) -> 0 | M30: =COUNTIFS('CONSOLIDADO DE INCIDENCIAS'!$M$2:$M$50,'AVANCE EJECUCIÓN '!$D30,'CONSOLIDADO DE INCIDENCIAS'!$D$2:$D$50,'CONSOLIDADO DE INCIDENCIAS'!$B$61) -> 0 | N30: Alejandra Cárdenas
C31: Estabilidad de Ambiente | D31: PT06 | E31: CP-EACS-026 | F31: Verificar la estabilidad, navegación básica y ejecución de los módulos críticos bajo la versión de .NET framework 4.8.1. | G31: Sistema estable sin caídas repentinas, navegación fluida y sin conflictos de compatibilidad en la infraestructura de .NET 4.8.1. | H31: =SUM(I31,J31,L31,M31) -> 0 | I31: {=SUMPRODUCT(COUNTIFS('CONSOLIDADO DE INCIDENCIAS'!$M$2:$M$50, 'AVANCE EJECUCIÓN '!$D31, 'CONSOLIDADO DE INCIDENCIAS'!$D$2:$D$50, 'CONSOLIDADO DE INCIDENCIAS'!$B$58:$B$59))} -> 0 | J31: {=SUMPRODUCT(COUNTIFS('CONSOLIDADO DE INCIDENCIAS'!$M$2:$M$50, 'AVANCE EJECUCIÓN '!$D31, 'CONSOLIDADO DE INCIDENCIAS'!$D$2:$D$50, 'CONSOLIDADO DE INCIDENCIAS'!$B$55:$B$57))} -> 0 | K31: {=SUMPRODUCT(COUNTIFS('CONSOLIDADO DE INCIDENCIAS'!$M$2:$M$50, 'AVANCE EJECUCIÓN '!$D31, 'CONSOLIDADO DE INCIDENCIAS'!$W$2:$W$50, 'CONSOLIDADO DE INCIDENCIAS'!$B$55:$B$57))} -> 0 | L31: =COUNTIFS('CONSOLIDADO DE INCIDENCIAS'!$M$2:$M$50,'AVANCE EJECUCIÓN '!$D31,'CONSOLIDADO DE INCIDENCIAS'!$D$2:$D$50,'CONSOLIDADO DE INCIDENCIAS'!$B$60) -> 0 | M31: =COUNTIFS('CONSOLIDADO DE INCIDENCIAS'!$M$2:$M$50,'AVANCE EJECUCIÓN '!$D31,'CONSOLIDADO DE INCIDENCIAS'!$D$2:$D$50,'CONSOLIDADO DE INCIDENCIAS'!$B$61) -> 0 | N31: Alejandra Cárdenas
B32: PRUEBAS DE REGRESIÓN | C32: Revisión y levantamiento de incidencias | D32: PR01 | E32: CP-EACS-027 | F32: Revisar y cerrar incidencias | G32: Totalidad de defectos corregidos por desarrollo validados exitosamente, con su estado actualizado a "Cerrado". | H32: =SUM(I32,J32,L32,M32) -> 0 | I32: {=SUMPRODUCT(COUNTIFS('CONSOLIDADO DE INCIDENCIAS'!$M$2:$M$50, 'AVANCE EJECUCIÓN '!$D32, 'CONSOLIDADO DE INCIDENCIAS'!$D$2:$D$50, 'CONSOLIDADO DE INCIDENCIAS'!$B$58:$B$59))} -> 0 | J32: {=SUMPRODUCT(COUNTIFS('CONSOLIDADO DE INCIDENCIAS'!$M$2:$M$50, 'AVANCE EJECUCIÓN '!$D32, 'CONSOLIDADO DE INCIDENCIAS'!$D$2:$D$50, 'CONSOLIDADO DE INCIDENCIAS'!$B$55:$B$57))} -> 0 | K32: {=SUMPRODUCT(COUNTIFS('CONSOLIDADO DE INCIDENCIAS'!$M$2:$M$50, 'AVANCE EJECUCIÓN '!$D32, 'CONSOLIDADO DE INCIDENCIAS'!$W$2:$W$50, 'CONSOLIDADO DE INCIDENCIAS'!$B$55:$B$57))} -> 0 | L32: =COUNTIFS('CONSOLIDADO DE INCIDENCIAS'!$M$2:$M$50,'AVANCE EJECUCIÓN '!$D32,'CONSOLIDADO DE INCIDENCIAS'!$D$2:$D$50,'CONSOLIDADO DE INCIDENCIAS'!$B$60) -> 0 | M32: =COUNTIFS('CONSOLIDADO DE INCIDENCIAS'!$M$2:$M$50,'AVANCE EJECUCIÓN '!$D32,'CONSOLIDADO DE INCIDENCIAS'!$D$2:$D$50,'CONSOLIDADO DE INCIDENCIAS'!$B$61) -> 0 | N32: Alejandra Cárdenas
C33: Flujos Críticos de Regresión | D33: PR02 | E33: CP-EACS-028 | F33: Ejecutar flujos críticos del sistema. | G33: Procesos de negocio (rutas críticas y Happy Paths) completados y sin encontrar errores de severidad alta o bloqueante | H33: =SUM(I33,J33,L33,M33) -> 0 | I33: {=SUMPRODUCT(COUNTIFS('CONSOLIDADO DE INCIDENCIAS'!$M$2:$M$50, 'AVANCE EJECUCIÓN '!$D33, 'CONSOLIDADO DE INCIDENCIAS'!$D$2:$D$50, 'CONSOLIDADO DE INCIDENCIAS'!$B$58:$B$59))} -> 0 | J33: {=SUMPRODUCT(COUNTIFS('CONSOLIDADO DE INCIDENCIAS'!$M$2:$M$50, 'AVANCE EJECUCIÓN '!$D33, 'CONSOLIDADO DE INCIDENCIAS'!$D$2:$D$50, 'CONSOLIDADO DE INCIDENCIAS'!$B$55:$B$57))} -> 0 | K33: {=SUMPRODUCT(COUNTIFS('CONSOLIDADO DE INCIDENCIAS'!$M$2:$M$50, 'AVANCE EJECUCIÓN '!$D33, 'CONSOLIDADO DE INCIDENCIAS'!$W$2:$W$50, 'CONSOLIDADO DE INCIDENCIAS'!$B$55:$B$57))} -> 0 | L33: =COUNTIFS('CONSOLIDADO DE INCIDENCIAS'!$M$2:$M$50,'AVANCE EJECUCIÓN '!$D33,'CONSOLIDADO DE INCIDENCIAS'!$D$2:$D$50,'CONSOLIDADO DE INCIDENCIAS'!$B$60) -> 0 | M33: =COUNTIFS('CONSOLIDADO DE INCIDENCIAS'!$M$2:$M$50,'AVANCE EJECUCIÓN '!$D33,'CONSOLIDADO DE INCIDENCIAS'!$D$2:$D$50,'CONSOLIDADO DE INCIDENCIAS'!$B$61) -> 0 | N33: Alejandra Cárdenas
B34: TOTAL / RESUMEN | D34: =COUNTA(D6:D33) -> 8 | H34: =SUM(H6:H31) -> 0 | I34: =SUM(I6:I31) -> 0 | J34: =SUM(J6:J31) -> 0 | K34: =SUM(K6:K31) -> 0 | L34: =SUM(L6:L31) -> 0 | M34: =SUM(M6:M31) -> 0 | N34: Alejandra Cárdenas
B40: Leyenda
B41: BLOQUEANTE | C41: Funcionalidad con errores que no permiten continuar con la revisión
B42: PENDIENTE | C42: Funcionalidad pendiente de revisión por el equipo de QA
B43: EN PROCESO | C43: Funcionalidad en proceso de revisión por el equipo de QA
B44: CONCLUIDO | C44: Funcionalidad revisada completamente, pero se tiene incidencias pendientes
B45: CERRADO | C45: Funcionalidad revisada completamente, no se tiene incidencias pendientes
B46: POSTERGADO | C46: Funcionalidad postergada para un próximo paquete de mejoras

Sheet CONSOLIDADO DE INCIDENCIAS
A1: Nro. | B1: NRO. INCIDENCIA | C1: ITERACIÓN | D1: ESTADO | E1: FECHA DE REPORTE | F1: FECHA DE ATENCIÓN | G1: TIPO DE PRUEBA | H1: NAVEGADOR | I1: SISTEMA | J1: ROL | K1: MÓDULO | L1: FUNCIONALIDAD | M1: PROCESOS | N1: DESCRIPCIÓN | O1: DESCRIPCIÓN DE INCIDENCIA | P1: DETALLE | Q1: IMAGEN1 | R1: IMAGEN2 | S1: ANALISTA QA | T1: COMENTARIOS QA | U1: CRITICIDAD | V1: COMENTARIOS DESARROLLO | W1: ESTADO | X1: ANALISTA DESARROLLO | Y1: ANALISTA DESARROLLO 2 | Z1: FECHA SUBSANACIÓN
B54: Leyenda
B55: BLOQUEANTE | C55: Incidencia no permiten continuar con la revisión
B56: PENDIENTE | C56: Incidencia pendiente de revisión
B57: EN PROCESO | C57: Incidencia en proceso de revisión
B58: CONCLUIDO | C58: Incidencia revisada completamente, pero se tiene otras incidencias relacionadas pendientes
B59: CERRADO | C59: Incidencia revisada completamente, no se tiene incidencias relacionadas pendientes
B60: DESESTIMADO | C60: Incidencia que no requiere corrección o no corresponde al sistema.
B61: MEJORA | C61: Incidencia postergada para un próximo paquete de mejoras
B63: PRUEBAS FUNCIONALES | C63: Validan lo que hace el sistema
B64: PRUEBAS TECNICAS | C64: Verifican como lo hace el sistema
B65: PRUEBAS DE REGRESION | C65: Verifican que los cambios o actualizaciones no hayan roto lo que ya funcionaba
B67: ALTA | C67: Detiene por completo la operación del sistema y no existe ninguna alternativa para continuar
B68: MEDIA | C68: Afecta funciones importantes pero no vitales, y/o se tiene una solución alternativa para continuar.
B69: BAJA | C69: No afectan la operación ni la lógica del sistema
